Workbook

Sheet Total Notebooks (Final)
B1: Location | C1: Sl.No | D1: NAME OF THE SCHOOL | E1: 1st | F1: 80 pg | J1: 2nd | K1: 80 pg | O1: 3rd | P1: 80 pg | T1: 4th | U1: 80 pg | Y1: 5th | Z1: 160 | AA1: 6th | AB1: 160 pg | AC1: 7th | AD1: 160 pg | AE1: 8th | AF1: 160pg | AG1: 9th | AH1: 160pg | AJ1: 10th | AK1: 160 pg | AP1: No. of students | AQ1: Total Notebooks
E2: Total | F2: 1L | G2: 2L | H2: 4L | I2: SQ | J2: Total | K2: 1L | L2: 2L | M2: 4L | N2: SQ | O2: Total | P2: 1L | Q2: 2L | R2: 4L | S2: SQ | T2: Total | U2: 1L | V2: 2L | W2: 4L | X2: SQ | Y2: Total | Z2: 1L | AA2: Total | AB2: 1L | AC2: Total | AD2: 1L | AE2: Total | AF2: 1L | AG2: Total | AH2: 1L | AI2: LB | AJ2: Total | AK2: 1L | AL2: LB
B3: Belgaum | C3: 1 | D3: KHPS Gudaganahatti RC | E3: 12 | F3: =E3*1 -> 12 | G3: =E3*1 -> 12 | H3: =E3*1 -> 12 | I3: =E3*1 -> 12 | J3: 23 | K3: =J3*1 -> 23 | L3: =J3*1 -> 23 | M3: =J3*1 -> 23 | N3: =J3*1 -> 23 | O3: 29 | P3: =O3*1 -> 29 | Q3: =O3*1 -> 29 | R3: =O3*1 -> 29 | S3: =O3*1 -> 29 | T3: 26 | U3: =T3*1 -> 26 | V3: =U3*1 -> 26 | W3: =V3*1 -> 26 | X3: =W3*1 -> 26 | Y3: 40 | Z3: =Y3*8 -> 320 | AA3: 51 | AB3: =AA3*8 -> 408 | AC3: 50 | AD3: =AC3*8 -> 400 | AE3: 51 | AF3: =AE3*8 -> 408 | AH3: =AG3*8 -> 0 | AI3: =AG3*4 -> 0 | AK3: =AJ3*8 -> 0 | AL3: =AJ3*4 -> 0 | AP3: =E3+AM3+AJ3+AG3+AE3+AC3+AA3+Y3+T3+O3+J3 -> 282 | AQ3: =SUM(F3,G3,H3,I3,K3,L3,M3,N3,P3,Q3,R3,S3,U3,V3,W3,X3,Z3,AB3,AD3,AF3,AH3,AI3,AK3,AL3,AN3,AO3) -> 1896
B4: Belgaum | C4: 2 | D4: KHPGS Yamakanamaradi | E4: 5 | F4: =E4*1 -> 5 | G4: =E4*1 -> 5 | H4: =E4*1 -> 5 | I4: =E4*1 -> 5 | J4: 17 | K4: =J4*1 -> 17 | L4: =J4*1 -> 17 | M4: =J4*1 -> 17 | N4: =J4*1 -> 17 | O4: 15 | P4: =O4*1 -> 15 | Q4: =O4*1 -> 15 | R4: =O4*1 -> 15 | S4: =O4*1 -> 15 | T4: 19 | U4: =T4*1 -> 19 | V4: =U4*1 -> 19 | W4: =V4*1 -> 19 | X4: =W4*1 -> 19 | Y4: 21 | Z4: =Y4*8 -> 168 | AA4: 20 | AB4: =AA4*8 -> 160 | AC4: 33 | AD4: =AC4*8 -> 264 | AF4: =AE4*8 -> 0 | AH4: =AG4*8 -> 0 | AI4: =AG4*4 -> 0 | AK4: =AJ4*8 -> 0 | AL4: =AJ4*4 -> 0 | AP4: =E4+AM4+AJ4+AG4+AE4+AC4+AA4+Y4+T4+O4+J4 -> 130 | AQ4: =SUM(F4,G4,H4,I4,K4,L4,M4,N4,P4,Q4,R4,S4,U4,V4,W4,X4,Z4,AB4,AD4,AF4,AH4,AI4,AK4,AL4,AN4,AO4) -> 816
B5: Belgaum | C5: 3 | D5: KHPBS Yamakanamaradi | E5: 12 | F5: =E5*1 -> 12 | G5: =E5*1 -> 12 | H5: =E5*1 -> 12 | I5: =E5*1 -> 12 | J5: 15 | K5: =J5*1 -> 15 | L5: =J5*1 -> 15 | M5: =J5*1 -> 15 | N5: =J5*1 -> 15 | O5: 18 | P5: =O5*1 -> 18 | Q5: =O5*1 -> 18 | R5: =O5*1 -> 18 | S5: =O5*1 -> 18 | T5: 15 | U5: =T5*1 -> 15 | V5: =U5*1 -> 15 | W5: =V5*1 -> 15 | X5: =W5*1 -> 15 | Y5: 28 | Z5: =Y5*8 -> 224 | AA5: 22 | AB5: =AA5*8 -> 176 | AC5: 24 | AD5: =AC5*8 -> 192 | AF5: =AE5*8 -> 0 | AH5: =AG5*8 -> 0 | AI5: =AG5*4 -> 0 | AK5: =AJ5*8 -> 0 | AL5: =AJ5*4 -> 0 | AP5: =E5+AM5+AJ5+AG5+AE5+AC5+AA5+Y5+T5+O5+J5 -> 134 | AQ5: =SUM(F5,G5,H5,I5,K5,L5,M5,N5,P5,Q5,R5,S5,U5,V5,W5,X5,Z5,AB5,AD5,AF5,AH5,AI5,AK5,AL5,AN5,AO5) -> 832
B6: Belgaum | C6: 4 | D6: UEMPS(English Medium) Yamakanamaradi | E6: 18 | F6: =E6*1 -> 18 | G6: =E6*1 -> 18 | H6: =E6*1 -> 18 | I6: =E6*1 -> 18 | J6: 17 | K6: =J6*1 -> 17 | L6: =J6*1 -> 17 | M6: =J6*1 -> 17 | N6: =J6*1 -> 17 | O6: 29 | P6: =O6*1 -> 29 | Q6: =O6*1 -> 29 | R6: =O6*1 -> 29 | S6: =O6*1 -> 29 | T6: 26 | U6: =T6*1 -> 26 | V6: =U6*1 -> 26 | W6: =V6*1 -> 26 | X6: =W6*1 -> 26 | Y6: 25 | Z6: =Y6*8 -> 200 | AA6: 18 | AB6: =AA6*8 -> 144 | AC6: 28 | AD6: =AC6*8 -> 224 | AF6: =AE6*8 -> 0 | AH6: =AG6*8 -> 0 | AI6: =AG6*4 -> 0 | AK6: =AJ6*8 -> 0 | AL6: =AJ6*4 -> 0 | AP6: =E6+AM6+AJ6+AG6+AE6+AC6+AA6+Y6+T6+O6+J6 -> 161 | AQ6: =SUM(F6,G6,H6,I6,K6,L6,M6,N6,P6,Q6,R6,S6,U6,V6,W6,X6,Z6,AB6,AD6,AF6,AH6,AI6,AK6,AL6,AN6,AO6) -> 928
B7: Belgaum | C7: 5 | D7: UHPS Yamakanamaradi | E7: 22 | F7: =E7*1 -> 22 | G7: =E7*1 -> 22 | H7: =E7*1 -> 22 | I7: =E7*1 -> 22 | K7: =J7*1 -> 0 | L7: =J7*1 -> 0 | M7: =J7*1 -> 0 | N7: =J7*1 -> 0 | P7: =O7*1 -> 0 | Q7: =O7*1 -> 0 | R7: =O7*1 -> 0 | S7: =O7*1 -> 0 | U7: =T7*1 -> 0 | V7: =U7*1 -> 0 | W7: =V7*1 -> 0 | X7: =W7*1 -> 0 | Z7: =Y7*8 -> 0 | AB7: =AA7*8 -> 0 | AD7: =AC7*8 -> 0 | AF7: =AE7*8 -> 0 | AH7: =AG7*8 -> 0 | AI7: =AG7*4 -> 0 | AK7: =AJ7*8 -> 0 | AL7: =AJ7*4 -> 0 | AP7: =E7+AM7+AJ7+AG7+AE7+AC7+AA7+Y7+T7+O7+J7 -> 22 | AQ7: =SUM(F7,G7,H7,I7,K7,L7,M7,N7,P7,Q7,R7,S7,U7,V7,W7,X7,Z7,AB7,AD7,AF7,AH7,AI7,AK7,AL7,AN7,AO7) -> 88
B8: Belgaum | C8: 6 | D8: KHPS Hattaragi | E8: 25 | F8: =E8*1 -> 25 | G8: =E8*1 -> 25 | H8: =E8*1 -> 25 | I8: =E8*1 -> 25 | J8: 25 | K8: =J8*1 -> 25 | L8: =J8*1 -> 25 | M8: =J8*1 -> 25 | N8: =J8*1 -> 25 | O8: 20 | P8: =O8*1 -> 20 | Q8: =O8*1 -> 20 | R8: =O8*1 -> 20 | S8: =O8*1 -> 20 | T8: 20 | U8: =T8*1 -> 20 | V8: =U8*1 -> 20 | W8: =V8*1 -> 20 | X8: =W8*1 -> 20 | Y8: 18 | Z8: =Y8*8 -> 144 | AA8: 18 | AB8: =AA8*8 -> 144 | AC8: 20 | AD8: =AC8*8 -> 160 | AF8: =AE8*8 -> 0 | AH8: =AG8*8 -> 0 | AI8: =AG8*4 -> 0 | AK8: =AJ8*8 -> 0 | AL8: =AJ8*4 -> 0 | AP8: =E8+AM8+AJ8+AG8+AE8+AC8+AA8+Y8+T8+O8+J8 -> 146 | AQ8: =SUM(F8,G8,H8,I8,K8,L8,M8,N8,P8,Q8,R8,S8,U8,V8,W8,X8,Z8,AB8,AD8,AF8,AH8,AI8,AK8,AL8,AN8,AO8) -> 808
B9: Belgaum | C9: 7 | D9: KHPS Anandpur | E9: 12 | F9: =E9*1 -> 12 | G9: =E9*1 -> 12 | H9: =E9*1 -> 12 | I9: =E9*1 -> 12 | J9: 15 | K9: =J9*1 -> 15 | L9: =J9*1 -> 15 | M9: =J9*1 -> 15 | N9: =J9*1 -> 15 | O9: 8 | P9: =O9*1 -> 8 | Q9: =O9*1 -> 8 | R9: =O9*1 -> 8 | S9: =O9*1 -> 8 | T9: 10 | U9: =T9*1 -> 10 | V9: =U9*1 -> 10 | W9: =V9*1 -> 10 | X9: =W9*1 -> 10 | Y9: 17 | Z9: =Y9*8 -> 136 | AA9: 20 | AB9: =AA9*8 -> 160 | AC9: 13 | AD9: =AC9*8 -> 104 | AF9: =AE9*8 -> 0 | AH9: =AG9*8 -> 0 | AI9: =AG9*4 -> 0 | AK9: =AJ9*8 -> 0 | AL9: =AJ9*4 -> 0 | AP9: =E9+AM9+AJ9+AG9+AE9+AC9+AA9+Y9+T9+O9+J9 -> 95 | AQ9: =SUM(F9,G9,H9,I9,K9,L9,M9,N9,P9,Q9,R9,S9,U9,V9,W9,X9,Z9,AB9,AD9,AF9,AH9,AI9,AK9,AL9,AN9,AO9) -> 580
B10: Belgaum | C10: 8 | D10: KHPS Hunnur Masthiholi | E10: 5 | F10: =E10*1 -> 5 | G10: =E10*1 -> 5 | H10: =E10*1 -> 5 | I10: =E10*1 -> 5 | J10: 10 | K10: =J10*1 -> 10 | L10: =J10*1 -> 10 | M10: =J10*1 -> 10 | N10: =J10*1 -> 10 | O10: 12 | P10: =O10*1 -> 12 | Q10: =O10*1 -> 12 | R10: =O10*1 -> 12 | S10: =O10*1 -> 12 | T10: 5 | U10: =T10*1 -> 5 | V10: =U10*1 -> 5 | W10: =V10*1 -> 5 | X10: =W10*1 -> 5 | Y10: 9 | Z10: =Y10*8 -> 72 | AA10: 12 | AB10: =AA10*8 -> 96 | AC10: 11 | AD10: =AC10*8 -> 88 | AF10: =AE10*8 -> 0 | AH10: =AG10*8 -> 0 | AI10: =AG10*4 -> 0 | AK10: =AJ10*8 -> 0 | AL10: =AJ10*4 -> 0 | AP10: =E10+AM10+AJ10+AG10+AE10+AC10+AA10+Y10+T10+O10+J10 -> 64 | AQ10: =SUM(F10,G10,H10,I10,K10,L10,M10,N10,P10,Q10,R10,S10,U10,V10,W10,X10,Z10,AB10,AD10,AF10,AH10,AI10,AK10,AL10,AN10,AO10) -> 384
B11: Belgaum | C11: 9 | D11: KHPS Managutti | E11: 14 | F11: =E11*1 -> 14 | G11: =E11*1 -> 14 | H11: =E11*1 -> 14 | I11: =E11*1 -> 14 | J11: 25 | K11: =J11*1 -> 25 | L11: =J11*1 -> 25 | M11: =J11*1 -> 25 | N11: =J11*1 -> 25 | O11: 28 | P11: =O11*1 -> 28 | Q11: =O11*1 -> 28 | R11: =O11*1 -> 28 | S11: =O11*1 -> 28 | T11: 24 | U11: =T11*1 -> 24 | V11: =U11*1 -> 24 | W11: =V11*1 -> 24 | X11: =W11*1 -> 24 | Y11: 21 | Z11: =Y11*8 -> 168 | AA11: 41 | AB11: =AA11*8 -> 328 | AC11: 30 | AD11: =AC11*8 -> 240 | AF11: =AE11*8 -> 0 | AH11: =AG11*8 -> 0 | AI11: =AG11*4 -> 0 | AK11: =AJ11*8 -> 0 | AL11: =AJ11*4 -> 0 | AP11: =E11+AM11+AJ11+AG11+AE11+AC11+AA11+Y11+T11+O11+J11 -> 183 | AQ11: =SUM(F11,G11,H11,I11,K11,L11,M11,N11,P11,Q11,R11,S11,U11,V11,W11,X11,Z11,AB11,AD11,AF11,AH11,AI11,AK11,AL11,AN11,AO11) -> 1100
B12: Belgaum | C12: 10 | D12: MHPS Managutti | E12: 6 | F12: =E12*1 -> 6 | G12: =E12*1 -> 6 | H12: =E12*1 -> 6 | I12: =E12*1 -> 6 | J12: 13 | K12: =J12*1 -> 13 | L12: =J12*1 -> 13 | M12: =J12*1 -> 13 | N12: =J12*1 -> 13 | O12: 19 | P12: =O12*1 -> 19 | Q12: =O12*1 -> 19 | R12: =O12*1 -> 19 | S12: =O12*1 -> 19 | T12: 22 | U12: =T12*1 -> 22 | V12: =U12*1 -> 22 | W12: =V12*1 -> 22 | X12: =W12*1 -> 22 | Y12: 28 | Z12: =Y12*8 -> 224 | AA12: 16 | AB12: =AA12*8 -> 128 | AC12: 25 | AD12: =AC12*8 -> 200 | AF12: =AE12*8 -> 0 | AH12: =AG12*8 -> 0 | AI12: =AG12*4 -> 0 | AK12: =AJ12*8 -> 0 | AL12: =AJ12*4 -> 0 | AP12: =E12+AM12+AJ12+AG12+AE12+AC12+AA12+Y12+T12+O12+J12 -> 129 | AQ12: =SUM(F12,G12,H12,I12,K12,L12,M12,N12,P12,Q12,R12,S12,U12,V12,W12,X12,Z12,AB12,AD12,AF12,AH12,AI12,AK12,AL12,AN12,AO12) -> 792
B13: Belgaum | C13: 11 | D13: GHS Hunnur Masthiholi | F13: =E13*1 -> 0 | G13: =E13*1 -> 0 | H13: =E13*1 -> 0 | I13: =E13*1 -> 0 | K13: =J13*1 -> 0 | L13: =J13*1 -> 0 | M13: =J13*1 -> 0 | N13: =J13*1 -> 0 | P13: =O13*1 -> 0 | Q13: =O13*1 -> 0 | R13: =O13*1 -> 0 | S13: =O13*1 -> 0 | U13: =T13*1 -> 0 | V13: =U13*1 -> 0 | W13: =V13*1 -> 0 | X13: =W13*1 -> 0 | Z13: =Y13*8 -> 0 | AB13: =AA13*8 -> 0 | AD13: =AC13*8 -> 0 | AE13: 90 | AF13: =AE13*8 -> 720 | AG13: 170 | AH13: =AG13*8 -> 1360 | AI13: =AG13*4 -> 680 | AJ13: 120 | AK13: =AJ13*8 -> 960 | AL13: =AJ13*4 -> 480 | AP13: =E13+AM13+AJ13+AG13+AE13+AC13+AA13+Y13+T13+O13+J13 -> 380 | AQ13: =SUM(F13,G13,H13,I13,K13,L13,M13,N13,P13,Q13,R13,S13,U13,V13,W13,X13,Z13,AB13,AD13,AF13,AH13,AI13,AK13,AL13,AN13,AO13) -> 4200
B14: Belgaum | C14: 12 | D14: GHS Naganur KM | F14: =E14*1 -> 0 | G14: =E14*1 -> 0 | H14: =E14*1 -> 0 | I14: =E14*1 -> 0 | K14: =J14*1 -> 0 | L14: =J14*1 -> 0 | M14: =J14*1 -> 0 | N14: =J14*1 -> 0 | P14: =O14*1 -> 0 | Q14: =O14*1 -> 0 | R14: =O14*1 -> 0 | S14: =O14*1 -> 0 | U14: =T14*1 -> 0 | V14: =U14*1 -> 0 | W14: =V14*1 -> 0 | X14: =W14*1 -> 0 | Z14: =Y14*8 -> 0 | AB14: =AA14*8 -> 0 | AD14: =AC14*8 -> 0 | AE14: 50 | AF14: =AE14*8 -> 400 | AG14: 49 | AH14: =AG14*8 -> 392 | AI14: =AG14*4 -> 196 | AJ14: 49 | AK14: =AJ14*8 -> 392 | AL14: =AJ14*4 -> 196 | AP14: =E14+AM14+AJ14+AG14+AE14+AC14+AA14+Y14+T14+O14+J14 -> 148 | AQ14: =SUM(F14,G14,H14,I14,K14,L14,M14,N14,P14,Q14,R14,S14,U14,V14,W14,X14,Z14,AB14,AD14,AF14,AH14,AI14,AK14,AL14,AN14,AO14) -> 1576
B15: Belgaum | C15: 13 | D15: GHS Attihal | F15: =E15*1 -> 0 | G15: =E15*1 -> 0 | H15: =E15*1 -> 0 | I15: =E15*1 -> 0 | K15: =J15*1 -> 0 | L15: =J15*1 -> 0 | M15: =J15*1 -> 0 | N15: =J15*1 -> 0 | P15: =O15*1 -> 0 | Q15: =O15*1 -> 0 | R15: =O15*1 -> 0 | S15: =O15*1 -> 0 | U15: =T15*1 -> 0 | V15: =U15*1 -> 0 | W15: =V15*1 -> 0 | X15: =W15*1 -> 0 | Z15: =Y15*8 -> 0 | AB15: =AA15*8 -> 0 | AD15: =AC15*8 -> 0 | AE15: 63 | AF15: =AE15*8 -> 504 | AG15: 71 | AH15: =AG15*8 -> 568 | AI15: =AG15*4 -> 284 | AJ15: 52 | AK15: =AJ15*8 -> 416 | AL15: =AJ15*4 -> 208 | AP15: =E15+AM15+AJ15+AG15+AE15+AC15+AA15+Y15+T15+O15+J15 -> 186 | AQ15: =SUM(F15,G15,H15,I15,K15,L15,M15,N15,P15,Q15,R15,S15,U15,V15,W15,X15,Z15,AB15,AD15,AF15,AH15,AI15,AK15,AL15,AN15,AO15) -> 1980
B16: Belgaum | C16: 14 | D16: KLPS Halegudaganatti | E16: 13 | F16: =E16*1 -> 13 | G16: =E16*1 -> 13 | H16: =E16*1 -> 13 | I16: =E16*1 -> 13 | J16: 18 | K16: =J16*1 -> 18 | L16: =J16*1 -> 18 | M16: =J16*1 -> 18 | N16: =J16*1 -> 18 | O16: 12 | P16: =O16*1 -> 12 | Q16: =O16*1 -> 12 | R16: =O16*1 -> 12 | S16: =O16*1 -> 12 | T16: 17 | U16: =T16*1 -> 17 | V16: =U16*1 -> 17 | W16: =V16*1 -> 17 | X16: =W16*1 -> 17 | Y16: 16 | Z16: =Y16*8 -> 128 | AA16: 13 | AB16: =AA16*8 -> 104 | AC16: 15 | AD16: =AC16*8 -> 120 | AF16: =AE16*8 -> 0 | AH16: =AG16*8 -> 0 | AI16: =AG16*4 -> 0 | AK16: =AJ16*8 -> 0 | AL16: =AJ16*4 -> 0 | AP16: =E16+AM16+AJ16+AG16+AE16+AC16+AA16+Y16+T16+O16+J16 -> 104 | AQ16: =SUM(F16,G16,H16,I16,K16,L16,M16,N16,P16,Q16,R16,S16,U16,V16,W16,X16,Z16,AB16,AD16,AF16,AH16,AI16,AK16,AL16,AN16,AO16) -> 592
B17: Belgaum | C17: 15 | D17: KLPS Dadbanahatti | E17: 10 | F17: =E17*1 -> 10 | G17: =E17*1 -> 10 | H17: =E17*1 -> 10 | I17: =E17*1 -> 10 | J17: 12 | K17: =J17*1 -> 12 | L17: =J17*1 -> 12 | M17: =J17*1 -> 12 | N17: =J17*1 -> 12 | O17: 13 | P17: =O17*1 -> 13 | Q17: =O17*1 -> 13 | R17: =O17*1 -> 13 | S17: =O17*1 -> 13 | T17: 13 | U17: =T17*1 -> 13 | V17: =U17*1 -> 13 | W17: =V17*1 -> 13 | X17: =W17*1 -> 13 | Y17: 14 | Z17: =Y17*8 -> 112 | AB17: =AA17*8 -> 0 | AD17: =AC17*8 -> 0 | AF17: =AE17*8 -> 0 | AH17: =AG17*8 -> 0 | AI17: =AG17*4 -> 0 | AK17: =AJ17*8 -> 0 | AL17: =AJ17*4 -> 0 | AP17: =E17+AM17+AJ17+AG17+AE17+AC17+AA17+Y17+T17+O17+J17 -> 62 | AQ17: =SUM(F17,G17,H17,I17,K17,L17,M17,N17,P17,Q17,R17,S17,U17,V17,W17,X17,Z17,AB17,AD17,AF17,AH17,AI17,AK17,AL17,AN17,AO17) -> 304
B18: Hubballi | C18: 16 | D18: KHPS Itigatti Hubballi | E18: 42 | F18: =E18*1 -> 42 | G18: =E18*1 -> 42 | H18: =E18*1 -> 42 | I18: =E18*1 -> 42 | J18: 43 | K18: =J18*1 -> 43 | L18: =J18*1 -> 43 | M18: =J18*1 -> 43 | N18: =J18*1 -> 43 | O18: 40 | P18: =O18*1 -> 40 | Q18: =O18*1 -> 40 | R18: =O18*1 -> 40 | S18: =O18*1 -> 40 | T18: 45 | U18: =T18*1 -> 45 | V18: =U18*1 -> 45 | W18: =V18*1 -> 45 | X18: =W18*1 -> 45 | Y18: 45 | Z18: =Y18*8 -> 360 | AA18: 60 | AB18: =AA18*8 -> 480 | AC18: 62 | AD18: =AC18*8 -> 496 | AF18: =AE18*8 -> 0 | AH18: =AG18*8 -> 0 | AI18: =AG18*4 -> 0 | AK18: =AJ18*8 -> 0 | AL18: =AJ18*4 -> 0 | AP18: =E18+AM18+AJ18+AG18+AE18+AC18+AA18+Y18+T18+O18+J18 -> 337 | AQ18: =SUM(F18,G18,H18,I18,K18,L18,M18,N18,P18,Q18,R18,S18,U18,V18,W18,X18,Z18,AB18,AD18,AF18,AH18,AI18,AK18,AL18,AN18,AO18) -> 2016
B19: Belgaum | C19: 17 | D19: KHPS Benkanhalli | E19: 20 | F19: =E19*1 -> 20 | G19: =E19*1 -> 20 | H19: =E19*1 -> 20 | I19: =E19*1 -> 20 | J19: 41 | K19: =J19*1 -> 41 | L19: =J19*1 -> 41 | M19: =J19*1 -> 41 | N19: =J19*1 -> 41 | O19: 30 | P19: =O19*1 -> 30 | Q19: =O19*1 -> 30 | R19: =O19*1 -> 30 | S19: =O19*1 -> 30 | T19: 28 | U19: =T19*1 -> 28 | V19: =U19*1 -> 28 | W19: =V19*1 -> 28 | X19: =W19*1 -> 28 | Y19: 36 | Z19: =Y19*8 -> 288 | AA19: 33 | AB19: =AA19*8 -> 264 | AC19: 47 | AD19: =AC19*8 -> 376 | AF19: =AE19*8 -> 0 | AH19: =AG19*8 -> 0 | AI19: =AG19*4 -> 0 | AK19: =AJ19*8 -> 0 | AL19: =AJ19*4 -> 0 | AP19: =E19+AM19+AJ19+AG19+AE19+AC19+AA19+Y19+T19+O19+J19 -> 235 | AQ19: =SUM(F19,G19,H19,I19,K19,L19,M19,N19,P19,Q19,R19,S19,U19,V19,W19,X19,Z19,AB19,AD19,AF19,AH19,AI19,AK19,AL19,AN19,AO19) -> 1404
B20: Belgaum | C20: 18 | D20: KHPS Attihal | E20: 1 | F20: =E20*1 -> 1 | G20: =E20*1 -> 1 | H20: =E20*1 -> 1 | I20: =E20*1 -> 1 | J20: 9 | K20: =J20*1 -> 9 | L20: =J20*1 -> 9 | M20: =J20*1 -> 9 | N20: =J20*1 -> 9 | O20: 7 | P20: =O20*1 -> 7 | Q20: =O20*1 -> 7 | R20: =O20*1 -> 7 | S20: =O20*1 -> 7 | T20: 10 | U20: =T20*1 -> 10 | V20: =U20*1 -> 10 | W20: =V20*1 -> 10 | X20: =W20*1 -> 10 | Y20: 7 | Z20: =Y20*8 -> 56 | AA20: 13 | AB20: =AA20*8 -> 104 | AC20: 10 | AD20: =AC20*8 -> 80 | AF20: =AE20*8 -> 0 | AH20: =AG20*8 -> 0 | AI20: =AG20*4 -> 0 | AK20: =AJ20*8 -> 0 | AL20: =AJ20*4 -> 0 | AP20: =E20+AM20+AJ20+AG20+AE20+AC20+AA20+Y20+T20+O20+J20 -> 57 | AQ20: =SUM(F20,G20,H20,I20,K20,L20,M20,N20,P20,Q20,R20,S20,U20,V20,W20,X20,Z20,AB20,AD20,AF20,AH20,AI20,AK20,AL20,AN20,AO20) -> 348
B21: Belgaum | C21: 19 | D21: KHPS Majati | E21: 20 | F21: =E21*1 -> 20 | G21: =E21*1 -> 20 | H21: =E21*1 -> 20 | I21: =E21*1 -> 20 | J21: 31 | K21: =J21*1 -> 31 | L21: =J21*1 -> 31 | M21: =J21*1 -> 31 | N21: =J21*1 -> 31 | O21: 42 | P21: =O21*1 -> 42 | Q21: =O21*1 -> 42 | R21: =O21*1 -> 42 | S21: =O21*1 -> 42 | T21: 41 | U21: =T21*1 -> 41 | V21: =U21*1 -> 41 | W21: =V21*1 -> 41 | X21: =W21*1 -> 41 | Y21: 36 | Z21: =Y21*8 -> 288 | AA21: 38 | AB21: =AA21*8 -> 304 | AC21: 31 | AD21: =AC21*8 -> 248 | AF21: =AE21*8 -> 0 | AH21: =AG21*8 -> 0 | AI21: =AG21*4 -> 0 | AK21: =AJ21*8 -> 0 | AL21: =AJ21*4 -> 0 | AP21: =E21+AM21+AJ21+AG21+AE21+AC21+AA21+Y21+T21+O21+J21 -> 239 | AQ21: =SUM(F21,G21,H21,I21,K21,L21,M21,N21,P21,Q21,R21,S21,U21,V21,W21,X21,Z21,AB21,AD21,AF21,AH21,AI21,AK21,AL21,AN21,AO21) -> 1376
B22: Belgaum | C22: 20 | D22: GHS Nerli | F22: =E22*1 -> 0 | G22: =E22*1 -> 0 | H22: =E22*1 -> 0 | I22: =E22*1 -> 0 | K22: =J22*1 -> 0 | L22: =J22*1 -> 0 | M22: =J22*1 -> 0 | N22: =J22*1 -> 0 | P22: =O22*1 -> 0 | Q22: =O22*1 -> 0 | R22: =O22*1 -> 0 | S22: =O22*1 -> 0 | U22: =T22*1 -> 0 | V22: =U22*1 -> 0 | W22: =V22*1 -> 0 | X22: =W22*1 -> 0 | Z22: =Y22*8 -> 0 | AB22: =AA22*8 -> 0 | AD22: =AC22*8 -> 0 | AE22: 96 | AF22: =AE22*8 -> 768 | AG22: 110 | AH22: =AG22*8 -> 880 | AI22: =AG22*4 -> 440 | AJ22: 100 | AK22: =AJ22*8 -> 800 | AL22: =AJ22*4 -> 400 | AP22: =E22+AM22+AJ22+AG22+AE22+AC22+AA22+Y22+T22+O22+J22 -> 306 | AQ22: =SUM(F22,G22,H22,I22,K22,L22,M22,N22,P22,Q22,R22,S22,U22,V22,W22,X22,Z22,AB22,AD22,AF22,AH22,AI22,AK22,AL22,AN22,AO22) -> 3288
B23: Belgaum | C23: 21 | D23: GHS Kochari | F23: =E23*1 -> 0 | G23: =E23*1 -> 0 | H23: =E23*1 -> 0 | I23: =E23*1 -> 0 | K23: =J23*1 -> 0 | L23: =J23*1 -> 0 | M23: =J23*1 -> 0 | N23: =J23*1 -> 0 | P23: =O23*1 -> 0 | Q23: =O23*1 -> 0 | R23: =O23*1 -> 0 | S23: =O23*1 -> 0 | U23: =T23*1 -> 0 | V23: =U23*1 -> 0 | W23: =V23*1 -> 0 | X23: =W23*1 -> 0 | Z23: =Y23*8 -> 0 | AB23: =AA23*8 -> 0 | AD23: =AC23*8 -> 0 | AE23: 65 | AF23: =AE23*8 -> 520 | AG23: 60 | AH23: =AG23*8 -> 480 | AI23: =AG23*4 -> 240 | AJ23: 63 | AK23: =AJ23*8 -> 504 | AL23: =AJ23*4 -> 252 | AP23: =E23+AM23+AJ23+AG23+AE23+AC23+AA23+Y23+T23+O23+J23 -> 188 | AQ23: =SUM(F23,G23,H23,I23,K23,L23,M23,N23,P23,Q23,R23,S23,U23,V23,W23,X23,Z23,AB23,AD23,AF23,AH23,AI23,AK23,AL23,AN23,AO23) -> 1996
B24: Belgaum | C24: 22 | D24: KHPS Aldal | E24: 7 | F24: =E24*1 -> 7 | G24: =E24*1 -> 7 | H24: =E24*1 -> 7 | I24: =E24*1 -> 7 | J24: 22 | K24: =J24*1 -> 22 | L24: =J24*1 -> 22 | M24: =J24*1 -> 22 | N24: =J24*1 -> 22 | O24: 17 | P24: =O24*1 -> 17 | Q24: =O24*1 -> 17 | R24: =O24*1 -> 17 | S24: =O24*1 -> 17 | T24: 16 | U24: =T24*1 -> 16 | V24: =U24*1 -> 16 | W24: =V24*1 -> 16 | X24: =W24*1 -> 16 | Y24: 24 | Z24: =Y24*8 -> 192 | AA24: 23 | AB24: =AA24*8 -> 184 | AC24: 24 | AD24: =AC24*8 -> 192 | AF24: =AE24*8 -> 0 | AH24: =AG24*8 -> 0 | AI24: =AG24*4 -> 0 | AK24: =AJ24*8 -> 0 | AL24: =AJ24*4 -> 0 | AP24: =E24+AM24+AJ24+AG24+AE24+AC24+AA24+Y24+T24+O24+J24 -> 133 | AQ24: =SUM(F24,G24,H24,I24,K24,L24,M24,N24,P24,Q24,R24,S24,U24,V24,W24,X24,Z24,AB24,AD24,AF24,AH24,AI24,AK24,AL24,AN24,AO24) -> 816
B25: Belgaum | C25: 23 | D25: KHPBS Ullagadi Khanapur | E25: 22 | F25: =E25*1 -> 22 | G25: =E25*1 -> 22 | H25: =E25*1 -> 22 | I25: =E25*1 -> 22 | J25: 18 | K25: =J25*1 -> 18 | L25: =J25*1 -> 18 | M25: =J25*1 -> 18 | N25: =J25*1 -> 18 | O25: 20 | P25: =O25*1 -> 20 | Q25: =O25*1 -> 20 | R25: =O25*1 -> 20 | S25: =O25*1 -> 20 | T25: 18 | U25: =T25*1 -> 18 | V25: =U25*1 -> 18 | W25: =V25*1 -> 18 | X25: =W25*1 -> 18 | Y25: 21 | Z25: =Y25*8 -> 168 | AA25: 22 | AB25: =AA25*8 -> 176 | AC25: 18 | AD25: =AC25*8 -> 144 | AF25: =AE25*8 -> 0 | AH25: =AG25*8 -> 0 | AI25: =AG25*4 -> 0 | AK25: =AJ25*8 -> 0 | AL25: =AJ25*4 -> 0 | AP25: =E25+AM25+AJ25+AG25+AE25+AC25+AA25+Y25+T25+O25+J25 -> 139 | AQ25: =SUM(F25,G25,H25,I25,K25,L25,M25,N25,P25,Q25,R25,S25,U25,V25,W25,X25,Z25,AB25,AD25,AF25,AH25,AI25,AK25,AL25,AN25,AO25) -> 800
B26: Belgaum | C26: 24 | D26: KHPGS Ullagadi Khanapur | E26: 7 | F26: =E26*1 -> 7 | G26: =E26*1 -> 7 | H26: =E26*1 -> 7 | I26: =E26*1 -> 7 | J26: 7 | K26: =J26*1 -> 7 | L26: =J26*1 -> 7 | M26: =J26*1 -> 7 | N26: =J26*1 -> 7 | O26: 13 | P26: =O26*1 -> 13 | Q26: =O26*1 -> 13 | R26: =O26*1 -> 13 | S26: =O26*1 -> 13 | T26: 10 | U26: =T26*1 -> 10 | V26: =U26*1 -> 10 | W26: =V26*1 -> 10 | X26: =W26*1 -> 10 | Y26: 18 | Z26: =Y26*8 -> 144 | AA26: 21 | AB26: =AA26*8 -> 168 | AC26: 20 | AD26: =AC26*8 -> 160 | AF26: =AE26*8 -> 0 | AH26: =AG26*8 -> 0 | AI26: =AG26*4 -> 0 | AK26: =AJ26*8 -> 0 | AL26: =AJ26*4 -> 0 | AP26: =E26+AM26+AJ26+AG26+AE26+AC26+AA26+Y26+T26+O26+J26 -> 96 | AQ26: =SUM(F26,G26,H26,I26,K26,L26,M26,N26,P26,Q26,R26,S26,U26,V26,W26,X26,Z26,AB26,AD26,AF26,AH26,AI26,AK26,AL26,AN26,AO26) -> 620
B27: Belgaum | C27: 25 | D27: KHPS Naganur | E27: 6 | F27: =E27*1 -> 6 | G27: =E27*1 -> 6 | H27: =E27*1 -> 6 | I27: =E27*1 -> 6 | J27: 17 | K27: =J27*1 -> 17 | L27: =J27*1 -> 17 | M27: =J27*1 -> 17 | N27: =J27*1 -> 17 | O27: 28 | P27: =O27*1 -> 28 | Q27: =O27*1 -> 28 | R27: =O27*1 -> 28 | S27: =O27*1 -> 28 | T27: 19 | U27: =T27*1 -> 19 | V27: =U27*1 -> 19 | W27: =V27*1 -> 19 | X27: =W27*1 -> 19 | Y27: 24 | Z27: =Y27*8 -> 192 | AA27: 30 | AB27: =AA27*8 -> 240 | AC27: 30 | AD27: =AC27*8 -> 240 | AF27: =AE27*8 -> 0 | AH27: =AG27*8 -> 0 | AI27: =AG27*4 -> 0 | AK27: =AJ27*8 -> 0 | AL27: =AJ27*4 -> 0 | AP27: =E27+AM27+AJ27+AG27+AE27+AC27+AA27+Y27+T27+O27+J27 -> 154 | AQ27: =SUM(F27,G27,H27,I27,K27,L27,M27,N27,P27,Q27,R27,S27,U27,V27,W27,X27,Z27,AB27,AD27,AF27,AH27,AI27,AK27,AL27,AN27,AO27) -> 952
B28: Belgaum | C28: 26 | D28: KHPS Gudaganahatti Daddi | E28: 11 | F28: =E28*1 -> 11 | G28: =E28*1 -> 11 | H28: =E28*1 -> 11 | I28: =E28*1 -> 11 | J28: 12 | K28: =J28*1 -> 12 | L28: =J28*1 -> 12 | M28: =J28*1 -> 12 | N28: =J28*1 -> 12 | O28: 11 | P28: =O28*1 -> 11 | Q28: =O28*1 -> 11 | R28: =O28*1 -> 11 | S28: =O28*1 -> 11 | T28: 11 | U28: =T28*1 -> 11 | V28: =U28*1 -> 11 | W28: =V28*1 -> 11 | X28: =W28*1 -> 11 | Y28: 11 | Z28: =Y28*8 -> 88 | AA28: 15 | AB28: =AA28*8 -> 120 | AC28: 18 | AD28: =AC28*8 -> 144 | AF28: =AE28*8 -> 0 | AH28: =AG28*8 -> 0 | AI28: =AG28*4 -> 0 | AK28: =AJ28*8 -> 0 | AL28: =AJ28*4 -> 0 | AP28: =E28+AM28+AJ28+AG28+AE28+AC28+AA28+Y28+T28+O28+J28 -> 89 | AQ28: =SUM(F28,G28,H28,I28,K28,L28,M28,N28,P28,Q28,R28,S28,U28,V28,W28,X28,Z28,AB28,AD28,AF28,AH28,AI28,AK28,AL28,AN28,AO28) -> 532
B29: Belgaum | C29: 27 | D29: MHPS Daddi | E29: 24 | F29: =E29*1 -> 24 | G29: =E29*1 -> 24 | H29: =E29*1 -> 24 | I29: =E29*1 -> 24 | J29: 22 | K29: =J29*1 -> 22 | L29: =J29*1 -> 22 | M29: =J29*1 -> 22 | N29: =J29*1 -> 22 | O29: 23 | P29: =O29*1 -> 23 | Q29: =O29*1 -> 23 | R29: =O29*1 -> 23 | S29: =O29*1 -> 23 | T29: 19 | U29: =T29*1 -> 19 | V29: =U29*1 -> 19 | W29: =V29*1 -> 19 | X29: =W29*1 -> 19 | Y29: 24 | Z29: =Y29*8 -> 192 | AA29: 26 | AB29: =AA29*8 -> 208 | AC29: 24 | AD29: =AC29*8 -> 192 | AF29: =AE29*8 -> 0 | AH29: =AG29*8 -> 0 | AI29: =AG29*4 -> 0 | AK29: =AJ29*8 -> 0 | AL29: =AJ29*4 -> 0 | AP29: =E29+AM29+AJ29+AG29+AE29+AC29+AA29+Y29+T29+O29+J29 -> 162 | AQ29: =SUM(F29,G29,H29,I29,K29,L29,M29,N29,P29,Q29,R29,S29,U29,V29,W29,X29,Z29,AB29,AD29,AF29,AH29,AI29,AK29,AL29,AN29,AO29) -> 944
B30: Belgaum | C30: 28 | D30: KHPS Indiranagar | E30: 4 | F30: =E30*1 -> 4 | G30: =E30*1 -> 4 | H30: =E30*1 -> 4 | I30: =E30*1 -> 4 | J30: 11 | K30: =J30*1 -> 11 | L30: =J30*1 -> 11 | M30: =J30*1 -> 11 | N30: =J30*1 -> 11 | O30: 9 | P30: =O30*1 -> 9 | Q30: =O30*1 -> 9 | R30: =O30*1 -> 9 | S30: =O30*1 -> 9 | T30: 19 | U30: =T30*1 -> 19 | V30: =U30*1 -> 19 | W30: =V30*1 -> 19 | X30: =W30*1 -> 19 | Y30: 18 | Z30: =Y30*8 -> 144 | AA30: 20 | AB30: =AA30*8 -> 160 | AC30: 13 | AD30: =AC30*8 -> 104 | AF30: =AE30*8 -> 0 | AH30: =AG30*8 -> 0 | AI30: =AG30*4 -> 0 | AK30: =AJ30*8 -> 0 | AL30: =AJ30*4 -> 0 | AP30: =E30+AM30+AJ30+AG30+AE30+AC30+AA30+Y30+T30+O30+J30 -> 94 | AQ30: =SUM(F30,G30,H30,I30,K30,L30,M30,N30,P30,Q30,R30,S30,U30,V30,W30,X30,Z30,AB30,AD30,AF30,AH30,AI30,AK30,AL30,AN30,AO30) -> 580
B31: Belgaum | C31: 29 | D31: KHPS Daddi | E31: 12 | F31: =E31*1 -> 12 | G31: =E31*1 -> 12 | H31: =E31*1 -> 12 | I31: =E31*1 -> 12 | J31: 26 | K31: =J31*1 -> 26 | L31: =J31*1 -> 26 | M31: =J31*1 -> 26 | N31: =J31*1 -> 26 | O31: 20 | P31: =O31*1 -> 20 | Q31: =O31*1 -> 20 | R31: =O31*1 -> 20 | S31: =O31*1 -> 20 | T31: 27 | U31: =T31*1 -> 27 | V31: =U31*1 -> 27 | W31: =V31*1 -> 27 | X31: =W31*1 -> 27 | Y31: 17 | Z31: =Y31*8 -> 136 | AA31: 21 | AB31: =AA31*8 -> 168 | AC31: 29 | AD31: =AC31*8 -> 232 | AF31: =AE31*8 -> 0 | AH31: =AG31*8 -> 0 | AI31: =AG31*4 -> 0 | AK31: =AJ31*8 -> 0 | AL31: =AJ31*4 -> 0 | AP31: =E31+AM31+AJ31+AG31+AE31+AC31+AA31+Y31+T31+O31+J31 -> 152 | AQ31: =SUM(F31,G31,H31,I31,K31,L31,M31,N31,P31,Q31,R31,S31,U31,V31,W31,X31,Z31,AB31,AD31,AF31,AH31,AI31,AK31,AL31,AN31,AO31) -> 876
B32: Hubballi | C32: 30 | D32: GHPS Managundi | E32: 28 | F32: =E32*1 -> 28 | G32: =E32*1 -> 28 | H32: =E32*1 -> 28 | I32: =E32*1 -> 28 | J32: 43 | K32: =J32*1 -> 43 | L32: =J32*1 -> 43 | M32: =J32*1 -> 43 | N32: =J32*1 -> 43 | O32: 88 | P32: =O32*1 -> 88 | Q32: =O32*1 -> 88 | R32: =O32*1 -> 88 | S32: =O32*1 -> 88 | T32: 47 | U32: =T32*1 -> 47 | V32: =U32*1 -> 47 | W32: =V32*1 -> 47 | X32: =W32*1 -> 47 | Y32: 35 | Z32: =Y32*8 -> 280 | AA32: 55 | AB32: =AA32*8 -> 440 | AC32: 50 | AD32: =AC32*8 -> 400 | AF32: =AE32*8 -> 0 | AH32: =AG32*8 -> 0 | AI32: =AG32*4 -> 0 | AK32: =AJ32*8 -> 0 | AL32: =AJ32*4 -> 0 | AP32: =E32+AM32+AJ32+AG32+AE32+AC32+AA32+Y32+T32+O32+J32 -> 346 | AQ32: =SUM(F32,G32,H32,I32,K32,L32,M32,N32,P32,Q32,R32,S32,U32,V32,W32,X32,Z32,AB32,AD32,AF32,AH32,AI32,AK32,AL32,AN32,AO32) -> 1944
B33: Hubballi | C33: 31 | D33: GHS Managundi | F33: =E33*1 -> 0 | G33: =E33*1 -> 0 | H33: =E33*1 -> 0 | I33: =E33*1 -> 0 | K33: =J33*1 -> 0 | L33: =J33*1 -> 0 | M33: =J33*1 -> 0 | N33: =J33*1 -> 0 | P33: =O33*1 -> 0 | Q33: =O33*1 -> 0 | R33: =O33*1 -> 0 | S33: =O33*1 -> 0 | U33: =T33*1 -> 0 | V33: =U33*1 -> 0 | W33: =V33*1 -> 0 | X33: =W33*1 -> 0 | Z33: =Y33*8 -> 0 | AB33: =AA33*8 -> 0 | AD33: =AC33*8 -> 0 | AE33: 47 | AF33: =AE33*8 -> 376 | AG33: 96 | AH33: =AG33*8 -> 768 | AI33: =AG33*4 -> 384 | AJ33: 76 | AK33: =AJ33*8 -> 608 | AL33: =AJ33*4 -> 304 | AP33: =E33+AM33+AJ33+AG33+AE33+AC33+AA33+Y33+T33+O33+J33 -> 219 | AQ33: =SUM(F33,G33,H33,I33,K33,L33,M33,N33,P33,Q33,R33,S33,U33,V33,W33,X33,Z33,AB33,AD33,AF33,AH33,AI33,AK33,AL33,AN33,AO33) -> 2440
B34: Hubballi | C34: 32 | D34: GHPS Yarikoppa | E34: 12 | F34: =E34*1 -> 12 | G34: =E34*1 -> 12 | H34: =E34*1 -> 12 | I34: =E34*1 -> 12 | J34: 15 | K34: =J34*1 -> 15 | L34: =J34*1 -> 15 | M34: =J34*1 -> 15 | N34: =J34*1 -> 15 | O34: 21 | P34: =O34*1 -> 21 | Q34: =O34*1 -> 21 | R34: =O34*1 -> 21 | S34: =O34*1 -> 21 | T34: 19 | U34: =T34*1 -> 19 | V34: =U34*1 -> 19 | W34: =V34*1 -> 19 | X34: =W34*1 -> 19 | Y34: 18 | Z34: =Y34*8 -> 144 | AA34: 46 | AB34: =AA34*8 -> 368 | AC34: 41 | AD34: =AC34*8 -> 328 | AF34: =AE34*8 -> 0 | AH34: =AG34*8 -> 0 | AI34: =AG34*4 -> 0 | AK34: =AJ34*8 -> 0 | AL34: =AJ34*4 -> 0 | AP34: =E34+AM34+AJ34+AG34+AE34+AC34+AA34+Y34+T34+O34+J34 -> 172 | AQ34: =SUM(F34,G34,H34,I34,K34,L34,M34,N34,P34,Q34,R34,S34,U34,V34,W34,X34,Z34,AB34,AD34,AF34,AH34,AI34,AK34,AL34,AN34,AO34) -> 1108
B35: Hubballi | C35: 33 | D35: GHS Yarikoppa | F35: =E35*1 -> 0 | G35: =E35*1 -> 0 | H35: =E35*1 -> 0 | I35: =E35*1 -> 0 | K35: =J35*1 -> 0 | L35: =J35*1 -> 0 | M35: =J35*1 -> 0 | N35: =J35*1 -> 0 | P35: =O35*1 -> 0 | Q35: =O35*1 -> 0 | R35: =O35*1 -> 0 | S35: =O35*1 -> 0 | U35: =T35*1 -> 0 | V35: =U35*1 -> 0 | W35: =V35*1 -> 0 | X35: =W35*1 -> 0 | Z35: =Y35*8 -> 0 | AB35: =AA35*8 -> 0 | AD35: =AC35*8 -> 0 | AE35: 45 | AF35: =AE35*8 -> 360 | AG35: 70 | AH35: =AG35*8 -> 560 | AI35: =AG35*4 -> 280 | AJ35: 63 | AK35: =AJ35*8 -> 504 | AL35: =AJ35*4 -> 252 | AP35: =E35+AM35+AJ35+AG35+AE35+AC35+AA35+Y35+T35+O35+J35 -> 178 | AQ35: =SUM(F35,G35,H35,I35,K35,L35,M35,N35,P35,Q35,R35,S35,U35,V35,W35,X35,Z35,AB35,AD35,AF35,AH35,AI35,AK35,AL35,AN35,AO35) -> 1956
B36: Hubballi | C36: 34 | D36: KHPS Hosur | E36: 30 | F36: =E36*1 -> 30 | G36: =E36*1 -> 30 | H36: =E36*1 -> 30 | I36: =E36*1 -> 30 | J36: 35 | K36: =J36*1 -> 35 | L36: =J36*1 -> 35 | M36: =J36*1 -> 35 | N36: =J36*1 -> 35 | O36: 38 | P36: =O36*1 -> 38 | Q36: =O36*1 -> 38 | R36: =O36*1 -> 38 | S36: =O36*1 -> 38 | T36: 37 | U36: =T36*1 -> 37 | V36: =U36*1 -> 37 | W36: =V36*1 -> 37 | X36: =W36*1 -> 37 | Y36: 35 | Z36: =Y36*8 -> 280 | AA36: 38 | AB36: =AA36*8 -> 304 | AC36: 39 | AD36: =AC36*8 -> 312 | AF36: =AE36*8 -> 0 | AH36: =AG36*8 -> 0 | AI36: =AG36*4 -> 0 | AK36: =AJ36*8 -> 0 | AL36: =AJ36*4 -> 0 | AP36: =E36+AM36+AJ36+AG36+AE36+AC36+AA36+Y36+T36+O36+J36 -> 252 | AQ36: =SUM(F36,G36,H36,I36,K36,L36,M36,N36,P36,Q36,R36,S36,U36,V36,W36,X36,Z36,AB36,AD36,AF36,AH36,AI36,AK36,AL36,AN36,AO36) -> 1456
B37: Belgaum | C37: 35 | D37: Hebbal Boys School | E37: 13 | F37: =E37*1 -> 13 | G37: =E37*1 -> 13 | H37: =E37*1 -> 13 | I37: =E37*1 -> 13 | J37: 11 | K37: =J37*1 -> 11 | L37: =J37*1 -> 11 | M37: =J37*1 -> 11 | N37: =J37*1 -> 11 | O37: 11 | P37: =O37*1 -> 11 | Q37: =O37*1 -> 11 | R37: =O37*1 -> 11 | S37: =O37*1 -> 11 | T37: 10 | U37: =T37*1 -> 10 | V37: =U37*1 -> 10 | W37: =V37*1 -> 10 | X37: =W37*1 -> 10 | Y37: 17 | Z37: =Y37*8 -> 136 | AA37: 24 | AB37: =AA37*8 -> 192 | AC37: 26 | AD37: =AC37*8 -> 208 | AF37: =AE37*8 -> 0 | AH37: =AG37*8 -> 0 | AI37: =AG37*4 -> 0 | AK37: =AJ37*8 -> 0 | AL37: =AJ37*4 -> 0 | AP37: =E37+AM37+AJ37+AG37+AE37+AC37+AA37+Y37+T37+O37+J37 -> 112 | AQ37: =SUM(F37,G37,H37,I37,K37,L37,M37,N37,P37,Q37,R37,S37,U37,V37,W37,X37,Z37,AB37,AD37,AF37,AH37,AI37,AK37,AL37,AN37,AO37) -> 716
B38: Belgaum | C38: 36 | D38: Hebbal Girls School | E38: 22 | F38: =E38*1 -> 22 | G38: =E38*1 -> 22 | H38: =E38*1 -> 22 | I38: =E38*1 -> 22 | J38: 18 | K38: =J38*1 -> 18 | L38: =J38*1 -> 18 | M38: =J38*1 -> 18 | N38: =J38*1 -> 18 | O38: 16 | P38: =O38*1 -> 16 | Q38: =O38*1 -> 16 | R38: =O38*1 -> 16 | S38: =O38*1 -> 16 | T38: 14 | U38: =T38*1 -> 14 | V38: =U38*1 -> 14 | W38: =V38*1 -> 14 | X38: =W38*1 -> 14 | Y38: 22 | Z38: =Y38*8 -> 176 | AA38: 16 | AB38: =AA38*8 -> 128 | AC38: 19 | AD38: =AC38*8 -> 152 | AF38: =AE38*8 -> 0 | AH38: =AG38*8 -> 0 | AI38: =AG38*4 -> 0 | AK38: =AJ38*8 -> 0 | AL38: =AJ38*4 -> 0 | AP38: =E38+AM38+AJ38+AG38+AE38+AC38+AA38+Y38+T38+O38+J38 -> 127 | AQ38: =SUM(F38,G38,H38,I38,K38,L38,M38,N38,P38,Q38,R38,S38,U38,V38,W38,X38,Z38,AB38,AD38,AF38,AH38,AI38,AK38,AL38,AN38,AO38) -> 736
B39: Belgaum | C39: 37 | D39: KHPS Bidrewadi | E39: 8 | F39: =E39*1 -> 8 | G39: =E39*1 -> 8 | H39: =E39*1 -> 8 | I39: =E39*1 -> 8 | J39: 22 | K39: =J39*1 -> 22 | L39: =J39*1 -> 22 | M39: =J39*1 -> 22 | N39: =J39*1 -> 22 | O39: 20 | P39: =O39*1 -> 20 | Q39: =O39*1 -> 20 | R39: =O39*1 -> 20 | S39: =O39*1 -> 20 | T39: 15 | U39: =T39*1 -> 15 | V39: =U39*1 -> 15 | W39: =V39*1 -> 15 | X39: =W39*1 -> 15 | Y39: 21 | Z39: =Y39*8 -> 168 | AA39: 18 | AB39: =AA39*8 -> 144 | AC39: 22 | AD39: =AC39*8 -> 176 | AF39: =AE39*8 -> 0 | AH39: =AG39*8 -> 0 | AI39: =AG39*4 -> 0 | AK39: =AJ39*8 -> 0 | AL39: =AJ39*4 -> 0 | AP39: =E39+AM39+AJ39+AG39+AE39+AC39+AA39+Y39+T39+O39+J39 -> 126 | AQ39: =SUM(F39,G39,H39,I39,K39,L39,M39,N39,P39,Q39,R39,S39,U39,V39,W39,X39,Z39,AB39,AD39,AF39,AH39,AI39,AK39,AL39,AN39,AO39) -> 748
B40: Belgaum | C40: 38 | D40: KHPS Vaarimastiholli | E40: 5 | F40: =E40*1 -> 5 | G40: =E40*1 -> 5 | H40: =E40*1 -> 5 | I40: =E40*1 -> 5 | J40: 10 | K40: =J40*1 -> 10 | L40: =J40*1 -> 10 | M40: =J40*1 -> 10 | N40: =J40*1 -> 10 | O40: 12 | P40: =O40*1 -> 12 | Q40: =O40*1 -> 12 | R40: =O40*1 -> 12 | S40: =O40*1 -> 12 | T40: 5 | U40: =T40*1 -> 5 | V40: =U40*1 -> 5 | W40: =V40*1 -> 5 | X40: =W40*1 -> 5 | Y40: 10 | Z40: =Y40*8 -> 80 | AA40: 12 | AB40: =AA40*8 -> 96 | AC40: 12 | AD40: =AC40*8 -> 96 | AF40: =AE40*8 -> 0 | AH40: =AG40*8 -> 0 | AI40: =AG40*4 -> 0 | AK40: =AJ40*8 -> 0 | AL40: =AJ40*4 -> 0 | AP40: =E40+AM40+AJ40+AG40+AE40+AC40+AA40+Y40+T40+O40+J40 -> 66 | AQ40: =SUM(F40,G40,H40,I40,K40,L40,M40,N40,P40,Q40,R40,S40,U40,V40,W40,X40,Z40,AB40,AD40,AF40,AH40,AI40,AK40,AL40,AN40,AO40) -> 400
...

Sheet Schoolwise notebook count (Fin)
A1: Sl.No | B1: Location | C1: NAME OF THE SCHOOL | D1: 80 Pg | H1: 160 Pg | J1: Total | M1: Standardwise Noteboooks
D2: 1L | E2: 2L | F2: 4L | G2: SQ | H2: 1L | I2: LB | M2: 80 Pg | R2: 160 pg
A3: 1 | B3: Belgaum | C3: KHPS Gudaganahatti RC | D3: ='Total Notebooks (Final)'!F3+'Total Notebooks (Final)'!K3+'Total Notebooks (Final)'!P3+'Total Notebooks (Final)'!U3 -> 90 | E3: ='Total Notebooks (Final)'!G3+'Total Notebooks (Final)'!L3+'Total Notebooks (Final)'!Q3+'Total Notebooks (Final)'!V3 -> 90 | F3: ='Total Notebooks (Final)'!H3+'Total Notebooks (Final)'!M3+'Total Notebooks (Final)'!R3+'Total Notebooks (Final)'!W3 -> 90 | G3: ='Total Notebooks (Final)'!I3+'Total Notebooks (Final)'!N3+'Total Notebooks (Final)'!S3+'Total Notebooks (Final)'!X3 -> 90 | H3: ='Total Notebooks (Final)'!Z3+'Total Notebooks (Final)'!AB3+'Total Notebooks (Final)'!AD3+'Total Notebooks (Final)'!AF3+'Total Notebooks (Final)'!AH3+'Total Notebooks (Final)'!AK3 -> 1536 | I3: ='Total Notebooks (Final)'!AI3+'Total Notebooks (Final)'!AL3 -> 0 | J3: =SUM(D3:I3) -> 1896 | N3: 1st | O3: 2nd | P3: 3rd | Q3: 4th | R3: 5th | S3: 6th | T3: 7th | U3: 8th | V3: 9th | W3: 10th
A4: 2 | B4: Belgaum | C4: KHPGS Yamakanamaradi | D4: ='Total Notebooks (Final)'!F4+'Total Notebooks (Final)'!K4+'Total Notebooks (Final)'!P4+'Total Notebooks (Final)'!U4 -> 56 | E4: ='Total Notebooks (Final)'!G4+'Total Notebooks (Final)'!L4+'Total Notebooks (Final)'!Q4+'Total Notebooks (Final)'!V4 -> 56 | F4: ='Total Notebooks (Final)'!H4+'Total Notebooks (Final)'!M4+'Total Notebooks (Final)'!R4+'Total Notebooks (Final)'!W4 -> 56 | G4: ='Total Notebooks (Final)'!I4+'Total Notebooks (Final)'!N4+'Total Notebooks (Final)'!S4+'Total Notebooks (Final)'!X4 -> 56 | H4: ='Total Notebooks (Final)'!Z4+'Total Notebooks (Final)'!AB4+'Total Notebooks (Final)'!AD4+'Total Notebooks (Final)'!AF4+'Total Notebooks (Final)'!AH4+'Total Notebooks (Final)'!AK4 -> 592 | I4: ='Total Notebooks (Final)'!AI4+'Total Notebooks (Final)'!AL4 -> 0 | J4: =SUM(D4:I4) -> 816 | M4: 1L | N4: 1 | O4: 1 | P4: 2 | Q4: 2 | R4: 6 | S4: 6 | T4: 8 | U4: 8 | V4: 6 | W4: 8
A5: 3 | B5: Belgaum | C5: KHPBS Yamakanamaradi | D5: ='Total Notebooks (Final)'!F5+'Total Notebooks (Final)'!K5+'Total Notebooks (Final)'!P5+'Total Notebooks (Final)'!U5 -> 60 | E5: ='Total Notebooks (Final)'!G5+'Total Notebooks (Final)'!L5+'Total Notebooks (Final)'!Q5+'Total Notebooks (Final)'!V5 -> 60 | F5: ='Total Notebooks (Final)'!H5+'Total Notebooks (Final)'!M5+'Total Notebooks (Final)'!R5+'Total Notebooks (Final)'!W5 -> 60 | G5: ='Total Notebooks (Final)'!I5+'Total Notebooks (Final)'!N5+'Total Notebooks (Final)'!S5+'Total Notebooks (Final)'!X5 -> 60 | H5: ='Total Notebooks (Final)'!Z5+'Total Notebooks (Final)'!AB5+'Total Notebooks (Final)'!AD5+'Total Notebooks (Final)'!AF5+'Total Notebooks (Final)'!AH5+'Total Notebooks (Final)'!AK5 -> 592 | I5: ='Total Notebooks (Final)'!AI5+'Total Notebooks (Final)'!AL5 -> 0 | J5: =SUM(D5:I5) -> 832 | M5: 2L | N5: 1 | O5: 1 | P5: 1 | Q5: 1
A6: 4 | B6: Belgaum | C6: UEMPS(English Medium) Yamakanamaradi | D6: ='Total Notebooks (Final)'!F6+'Total Notebooks (Final)'!K6+'Total Notebooks (Final)'!P6+'Total Notebooks (Final)'!U6 -> 90 | E6: ='Total Notebooks (Final)'!G6+'Total Notebooks (Final)'!L6+'Total Notebooks (Final)'!Q6+'Total Notebooks (Final)'!V6 -> 90 | F6: ='Total Notebooks (Final)'!H6+'Total Notebooks (Final)'!M6+'Total Notebooks (Final)'!R6+'Total Notebooks (Final)'!W6 -> 90 | G6: ='Total Notebooks (Final)'!I6+'Total Notebooks (Final)'!N6+'Total Notebooks (Final)'!S6+'Total Notebooks (Final)'!X6 -> 90 | H6: ='Total Notebooks (Final)'!Z6+'Total Notebooks (Final)'!AB6+'Total Notebooks (Final)'!AD6+'Total Notebooks (Final)'!AF6+'Total Notebooks (Final)'!AH6+'Total Notebooks (Final)'!AK6 -> 568 | I6: ='Total Notebooks (Final)'!AI6+'Total Notebooks (Final)'!AL6 -> 0 | J6: =SUM(D6:I6) -> 928 | M6: SQ | N6: 1 | O6: 1 | P6: 1 | Q6: 1
A7: 5 | B7: Belgaum | C7: UHPS Yamakanamaradi | D7: ='Total Notebooks (Final)'!F7+'Total Notebooks (Final)'!K7+'Total Notebooks (Final)'!P7+'Total Notebooks (Final)'!U7 -> 22 | E7: ='Total Notebooks (Final)'!G7+'Total Notebooks (Final)'!L7+'Total Notebooks (Final)'!Q7+'Total Notebooks (Final)'!V7 -> 22 | F7: ='Total Notebooks (Final)'!H7+'Total Notebooks (Final)'!M7+'Total Notebooks (Final)'!R7+'Total Notebooks (Final)'!W7 -> 22 | G7: ='Total Notebooks (Final)'!I7+'Total Notebooks (Final)'!N7+'Total Notebooks (Final)'!S7+'Total Notebooks (Final)'!X7 -> 22 | H7: ='Total Notebooks (Final)'!Z7+'Total Notebooks (Final)'!AB7+'Total Notebooks (Final)'!AD7+'Total Notebooks (Final)'!AF7+'Total Notebooks (Final)'!AH7+'Total Notebooks (Final)'!AK7 -> 0 | I7: ='Total Notebooks (Final)'!AI7+'Total Notebooks (Final)'!AL7 -> 0 | J7: =SUM(D7:I7) -> 88 | M7: 4L | N7: 1 | O7: 1 | P7: 1 | Q7: 1 | R7: 2 | S7: 2
A8: 6 | B8: Belgaum | C8: KHPS Hattaragi | D8: ='Total Notebooks (Final)'!F8+'Total Notebooks (Final)'!K8+'Total Notebooks (Final)'!P8+'Total Notebooks (Final)'!U8 -> 90 | E8: ='Total Notebooks (Final)'!G8+'Total Notebooks (Final)'!L8+'Total Notebooks (Final)'!Q8+'Total Notebooks (Final)'!V8 -> 90 | F8: ='Total Notebooks (Final)'!H8+'Total Notebooks (Final)'!M8+'Total Notebooks (Final)'!R8+'Total Notebooks (Final)'!W8 -> 90 | G8: ='Total Notebooks (Final)'!I8+'Total Notebooks (Final)'!N8+'Total Notebooks (Final)'!S8+'Total Notebooks (Final)'!X8 -> 90 | H8: ='Total Notebooks (Final)'!Z8+'Total Notebooks (Final)'!AB8+'Total Notebooks (Final)'!AD8+'Total Notebooks (Final)'!AF8+'Total Notebooks (Final)'!AH8+'Total Notebooks (Final)'!AK8 -> 448 | I8: ='Total Notebooks (Final)'!AI8+'Total Notebooks (Final)'!AL8 -> 0 | J8: =SUM(D8:I8) -> 808 | M8: LB | V8: 4 | W8: 4
A9: 7 | B9: Belgaum | C9: KHPS Anandpur | D9: ='Total Notebooks (Final)'!F9+'Total Notebooks (Final)'!K9+'Total Notebooks (Final)'!P9+'Total Notebooks (Final)'!U9 -> 45 | E9: ='Total Notebooks (Final)'!G9+'Total Notebooks (Final)'!L9+'Total Notebooks (Final)'!Q9+'Total Notebooks (Final)'!V9 -> 45 | F9: ='Total Notebooks (Final)'!H9+'Total Notebooks (Final)'!M9+'Total Notebooks (Final)'!R9+'Total Notebooks (Final)'!W9 -> 45 | G9: ='Total Notebooks (Final)'!I9+'Total Notebooks (Final)'!N9+'Total Notebooks (Final)'!S9+'Total Notebooks (Final)'!X9 -> 45 | H9: ='Total Notebooks (Final)'!Z9+'Total Notebooks (Final)'!AB9+'Total Notebooks (Final)'!AD9+'Total Notebooks (Final)'!AF9+'Total Notebooks (Final)'!AH9+'Total Notebooks (Final)'!AK9 -> 400 | I9: ='Total Notebooks (Final)'!AI9+'Total Notebooks (Final)'!AL9 -> 0 | J9: =SUM(D9:I9) -> 580 | M9: Total per std | N9: =SUM(N4:N8) -> 4 | O9: =SUM(O4:O8) -> 4 | P9: =SUM(P4:P8) -> 5 | Q9: =SUM(Q4:Q8) -> 5 | R9: =SUM(R4:R8) -> 8 | S9: =SUM(S4:S8) -> 8 | T9: =SUM(T4:T8) -> 8 | U9: =SUM(U4:U8) -> 8 | ... W9: =SUM(W4:W8) -> 12
A10: 8 | B10: Belgaum | C10: KHPS Hunnur Masthiholi | D10: ='Total Notebooks (Final)'!F10+'Total Notebooks (Final)'!K10+'Total Notebooks (Final)'!P10+'Total Notebooks (Final)'!U10 -> 32 | E10: ='Total Notebooks (Final)'!G10+'Total Notebooks (Final)'!L10+'Total Notebooks (Final)'!Q10+'Total Notebooks (Final)'!V10 -> 32 | F10: ='Total Notebooks (Final)'!H10+'Total Notebooks (Final)'!M10+'Total Notebooks (Final)'!R10+'Total Notebooks (Final)'!W10 -> 32 | G10: ='Total Notebooks (Final)'!I10+'Total Notebooks (Final)'!N10+'Total Notebooks (Final)'!S10+'Total Notebooks (Final)'!X10 -> 32 | H10: ='Total Notebooks (Final)'!Z10+'Total Notebooks (Final)'!AB10+'Total Notebooks (Final)'!AD10+'Total Notebooks (Final)'!AF10+'Total Notebooks (Final)'!AH10+'Total Notebooks (Final)'!AK10 -> 256 | I10: ='Total Notebooks (Final)'!AI10+'Total Notebooks (Final)'!AL10 -> 0 | J10: =SUM(D10:I10) -> 384
A11: 9 | B11: Belgaum | C11: KHPS Managutti | D11: ='Total Notebooks (Final)'!F11+'Total Notebooks (Final)'!K11+'Total Notebooks (Final)'!P11+'Total Notebooks (Final)'!U11 -> 91 | E11: ='Total Notebooks (Final)'!G11+'Total Notebooks (Final)'!L11+'Total Notebooks (Final)'!Q11+'Total Notebooks (Final)'!V11 -> 91 | F11: ='Total Notebooks (Final)'!H11+'Total Notebooks (Final)'!M11+'Total Notebooks (Final)'!R11+'Total Notebooks (Final)'!W11 -> 91 | G11: ='Total Notebooks (Final)'!I11+'Total Notebooks (Final)'!N11+'Total Notebooks (Final)'!S11+'Total Notebooks (Final)'!X11 -> 91 | H11: ='Total Notebooks (Final)'!Z11+'Total Notebooks (Final)'!AB11+'Total Notebooks (Final)'!AD11+'Total Notebooks (Final)'!AF11+'Total Notebooks (Final)'!AH11+'Total Notebooks (Final)'!AK11 -> 736 | I11: ='Total Notebooks (Final)'!AI11+'Total Notebooks (Final)'!AL11 -> 0 | J11: =SUM(D11:I11) -> 1100
A12: 10 | B12: Belgaum | C12: MHPS Managutti | D12: ='Total Notebooks (Final)'!F12+'Total Notebooks (Final)'!K12+'Total Notebooks (Final)'!P12+'Total Notebooks (Final)'!U12 -> 60 | E12: ='Total Notebooks (Final)'!G12+'Total Notebooks (Final)'!L12+'Total Notebooks (Final)'!Q12+'Total Notebooks (Final)'!V12 -> 60 | F12: ='Total Notebooks (Final)'!H12+'Total Notebooks (Final)'!M12+'Total Notebooks (Final)'!R12+'Total Notebooks (Final)'!W12 -> 60 | G12: ='Total Notebooks (Final)'!I12+'Total Notebooks (Final)'!N12+'Total Notebooks (Final)'!S12+'Total Notebooks (Final)'!X12 -> 60 | H12: ='Total Notebooks (Final)'!Z12+'Total Notebooks (Final)'!AB12+'Total Notebooks (Final)'!AD12+'Total Notebooks (Final)'!AF12+'Total Notebooks (Final)'!AH12+'Total Notebooks (Final)'!AK12 -> 552 | I12: ='Total Notebooks (Final)'!AI12+'Total Notebooks (Final)'!AL12 -> 0 | J12: =SUM(D12:I12) -> 792
A13: 11 | B13: Belgaum | C13: GHS Hunnur Masthiholi | D13: ='Total Notebooks (Final)'!F13+'Total Notebooks (Final)'!K13+'Total Notebooks (Final)'!P13+'Total Notebooks (Final)'!U13 -> 0 | E13: ='Total Notebooks (Final)'!G13+'Total Notebooks (Final)'!L13+'Total Notebooks (Final)'!Q13+'Total Notebooks (Final)'!V13 -> 0 | F13: ='Total Notebooks (Final)'!H13+'Total Notebooks (Final)'!M13+'Total Notebooks (Final)'!R13+'Total Notebooks (Final)'!W13 -> 0 | G13: ='Total Notebooks (Final)'!I13+'Total Notebooks (Final)'!N13+'Total Notebooks (Final)'!S13+'Total Notebooks (Final)'!X13 -> 0 | H13: ='Total Notebooks (Final)'!Z13+'Total Notebooks (Final)'!AB13+'Total Notebooks (Final)'!AD13+'Total Notebooks (Final)'!AF13+'Total Notebooks (Final)'!AH13+'Total Notebooks (Final)'!AK13 -> 3040 | I13: ='Total Notebooks (Final)'!AI13+'Total Notebooks (Final)'!AL13 -> 1160 | J13: =SUM(D13:I13) -> 4200
A14: 12 | B14: Belgaum | C14: GHS Naganur KM | D14: ='Total Notebooks (Final)'!F14+'Total Notebooks (Final)'!K14+'Total Notebooks (Final)'!P14+'Total Notebooks (Final)'!U14 -> 0 | E14: ='Total Notebooks (Final)'!G14+'Total Notebooks (Final)'!L14+'Total Notebooks (Final)'!Q14+'Total Notebooks (Final)'!V14 -> 0 | F14: ='Total Notebooks (Final)'!H14+'Total Notebooks (Final)'!M14+'Total Notebooks (Final)'!R14+'Total Notebooks (Final)'!W14 -> 0 | G14: ='Total Notebooks (Final)'!I14+'Total Notebooks (Final)'!N14+'Total Notebooks (Final)'!S14+'Total Notebooks (Final)'!X14 -> 0 | H14: ='Total Notebooks (Final)'!Z14+'Total Notebooks (Final)'!AB14+'Total Notebooks (Final)'!AD14+'Total Notebooks (Final)'!AF14+'Total Notebooks (Final)'!AH14+'Total Notebooks (Final)'!AK14 -> 1184 | I14: ='Total Notebooks (Final)'!AI14+'Total Notebooks (Final)'!AL14 -> 392 | J14: =SUM(D14:I14) -> 1576
A15: 13 | B15: Belgaum | C15: GHS Attihal | D15: ='Total Notebooks (Final)'!F15+'Total Notebooks (Final)'!K15+'Total Notebooks (Final)'!P15+'Total Notebooks (Final)'!U15 -> 0 | E15: ='Total Notebooks (Final)'!G15+'Total Notebooks (Final)'!L15+'Total Notebooks (Final)'!Q15+'Total Notebooks (Final)'!V15 -> 0 | F15: ='Total Notebooks (Final)'!H15+'Total Notebooks (Final)'!M15+'Total Notebooks (Final)'!R15+'Total Notebooks (Final)'!W15 -> 0 | G15: ='Total Notebooks (Final)'!I15+'Total Notebooks (Final)'!N15+'Total Notebooks (Final)'!S15+'Total Notebooks (Final)'!X15 -> 0 | H15: ='Total Notebooks (Final)'!Z15+'Total Notebooks (Final)'!AB15+'Total Notebooks (Final)'!AD15+'Total Notebooks (Final)'!AF15+'Total Notebooks (Final)'!AH15+'Total Notebooks (Final)'!AK15 -> 1488 | I15: ='Total Notebooks (Final)'!AI15+'Total Notebooks (Final)'!AL15 -> 492 | J15: =SUM(D15:I15) -> 1980
A16: 14 | B16: Belgaum | C16: KLPS Halegudaganatti | D16: ='Total Notebooks (Final)'!F16+'Total Notebooks (Final)'!K16+'Total Notebooks (Final)'!P16+'Total Notebooks (Final)'!U16 -> 60 | E16: ='Total Notebooks (Final)'!G16+'Total Notebooks (Final)'!L16+'Total Notebooks (Final)'!Q16+'Total Notebooks (Final)'!V16 -> 60 | F16: ='Total Notebooks (Final)'!H16+'Total Notebooks (Final)'!M16+'Total Notebooks (Final)'!R16+'Total Notebooks (Final)'!W16 -> 60 | G16: ='Total Notebooks (Final)'!I16+'Total Notebooks (Final)'!N16+'Total Notebooks (Final)'!S16+'Total Notebooks (Final)'!X16 -> 60 | H16: ='Total Notebooks (Final)'!Z16+'Total Notebooks (Final)'!AB16+'Total Notebooks (Final)'!AD16+'Total Notebooks (Final)'!AF16+'Total Notebooks (Final)'!AH16+'Total Notebooks (Final)'!AK16 -> 352 | I16: ='Total Notebooks (Final)'!AI16+'Total Notebooks (Final)'!AL16 -> 0 | J16: =SUM(D16:I16) -> 592
A17: 15 | B17: Belgaum | C17: KLPS Dadbanahatti | D17: ='Total Notebooks (Final)'!F17+'Total Notebooks (Final)'!K17+'Total Notebooks (Final)'!P17+'Total Notebooks (Final)'!U17 -> 48 | E17: ='Total Notebooks (Final)'!G17+'Total Notebooks (Final)'!L17+'Total Notebooks (Final)'!Q17+'Total Notebooks (Final)'!V17 -> 48 | F17: ='Total Notebooks (Final)'!H17+'Total Notebooks (Final)'!M17+'Total Notebooks (Final)'!R17+'Total Notebooks (Final)'!W17 -> 48 | G17: ='Total Notebooks (Final)'!I17+'Total Notebooks (Final)'!N17+'Total Notebooks (Final)'!S17+'Total Notebooks (Final)'!X17 -> 48 | H17: ='Total Notebooks (Final)'!Z17+'Total Notebooks (Final)'!AB17+'Total Notebooks (Final)'!AD17+'Total Notebooks (Final)'!AF17+'Total Notebooks (Final)'!AH17+'Total Notebooks (Final)'!AK17 -> 112 | I17: ='Total Notebooks (Final)'!AI17+'Total Notebooks (Final)'!AL17 -> 0 | J17: =SUM(D17:I17) -> 304
A18: 16 | B18: Hubballi | C18: KHPS Itigatti Hubballi | D18: ='Total Notebooks (Final)'!F18+'Total Notebooks (Final)'!K18+'Total Notebooks (Final)'!P18+'Total Notebooks (Final)'!U18 -> 170 | E18: ='Total Notebooks (Final)'!G18+'Total Notebooks (Final)'!L18+'Total Notebooks (Final)'!Q18+'Total Notebooks (Final)'!V18 -> 170 | F18: ='Total Notebooks (Final)'!H18+'Total Notebooks (Final)'!M18+'Total Notebooks (Final)'!R18+'Total Notebooks (Final)'!W18 -> 170 | G18: ='Total Notebooks (Final)'!I18+'Total Notebooks (Final)'!N18+'Total Notebooks (Final)'!S18+'Total Notebooks (Final)'!X18 -> 170 | H18: ='Total Notebooks (Final)'!Z18+'Total Notebooks (Final)'!AB18+'Total Notebooks (Final)'!AD18+'Total Notebooks (Final)'!AF18+'Total Notebooks (Final)'!AH18+'Total Notebooks (Final)'!AK18 -> 1336 | I18: ='Total Notebooks (Final)'!AI18+'Total Notebooks (Final)'!AL18 -> 0 | J18: =SUM(D18:I18) -> 2016
A19: 17 | B19: Belgaum | C19: KHPS Benkanhalli | D19: ='Total Notebooks (Final)'!F19+'Total Notebooks (Final)'!K19+'Total Notebooks (Final)'!P19+'Total Notebooks (Final)'!U19 -> 119 | E19: ='Total Notebooks (Final)'!G19+'Total Notebooks (Final)'!L19+'Total Notebooks (Final)'!Q19+'Total Notebooks (Final)'!V19 -> 119 | F19: ='Total Notebooks (Final)'!H19+'Total Notebooks (Final)'!M19+'Total Notebooks (Final)'!R19+'Total Notebooks (Final)'!W19 -> 119 | G19: ='Total Notebooks (Final)'!I19+'Total Notebooks (Final)'!N19+'Total Notebooks (Final)'!S19+'Total Notebooks (Final)'!X19 -> 119 | H19: ='Total Notebooks (Final)'!Z19+'Total Notebooks (Final)'!AB19+'Total Notebooks (Final)'!AD19+'Total Notebooks (Final)'!AF19+'Total Notebooks (Final)'!AH19+'Total Notebooks (Final)'!AK19 -> 928 | I19: ='Total Notebooks (Final)'!AI19+'Total Notebooks (Final)'!AL19 -> 0 | J19: =SUM(D19:I19) -> 1404
A20: 18 | B20: Belgaum | C20: KHPS Attihal | D20: ='Total Notebooks (Final)'!F20+'Total Notebooks (Final)'!K20+'Total Notebooks (Final)'!P20+'Total Notebooks (Final)'!U20 -> 27 | E20: ='Total Notebooks (Final)'!G20+'Total Notebooks (Final)'!L20+'Total Notebooks (Final)'!Q20+'Total Notebooks (Final)'!V20 -> 27 | F20: ='Total Notebooks (Final)'!H20+'Total Notebooks (Final)'!M20+'Total Notebooks (Final)'!R20+'Total Notebooks (Final)'!W20 -> 27 | G20: ='Total Notebooks (Final)'!I20+'Total Notebooks (Final)'!N20+'Total Notebooks (Final)'!S20+'Total Notebooks (Final)'!X20 -> 27 | H20: ='Total Notebooks (Final)'!Z20+'Total Notebooks (Final)'!AB20+'Total Notebooks (Final)'!AD20+'Total Notebooks (Final)'!AF20+'Total Notebooks (Final)'!AH20+'Total Notebooks (Final)'!AK20 -> 240 | I20: ='Total Notebooks (Final)'!AI20+'Total Notebooks (Final)'!AL20 -> 0 | J20: =SUM(D20:I20) -> 348
A21: 19 | B21: Belgaum | C21: KHPS Majati | D21: ='Total Notebooks (Final)'!F21+'Total Notebooks (Final)'!K21+'Total Notebooks (Final)'!P21+'Total Notebooks (Final)'!U21 -> 134 | E21: ='Total Notebooks (Final)'!G21+'Total Notebooks (Final)'!L21+'Total Notebooks (Final)'!Q21+'Total Notebooks (Final)'!V21 -> 134 | F21: ='Total Notebooks (Final)'!H21+'Total Notebooks (Final)'!M21+'Total Notebooks (Final)'!R21+'Total Notebooks (Final)'!W21 -> 134 | G21: ='Total Notebooks (Final)'!I21+'Total Notebooks (Final)'!N21+'Total Notebooks (Final)'!S21+'Total Notebooks (Final)'!X21 -> 134 | H21: ='Total Notebooks (Final)'!Z21+'Total Notebooks (Final)'!AB21+'Total Notebooks (Final)'!AD21+'Total Notebooks (Final)'!AF21+'Total Notebooks (Final)'!AH21+'Total Notebooks (Final)'!AK21 -> 840 | I21: ='Total Notebooks (Final)'!AI21+'Total Notebooks (Final)'!AL21 -> 0 | J21: =SUM(D21:I21) -> 1376
... A31: 29 | B31: Belgaum | C31: KHPS Daddi | D31: ='Total Notebooks (Final)'!F31+'Total Notebooks (Final)'!K31+'Total Notebooks (Final)'!P31+'Total Notebooks (Final)'!U31 -> 85 | E31: ='Total Notebooks (Final)'!G31+'Total Notebooks (Final)'!L31+'Total Notebooks (Final)'!Q31+'Total Notebooks (Final)'!V31 -> 85 | F31: ='Total Notebooks (Final)'!H31+'Total Notebooks (Final)'!M31+'Total Notebooks (Final)'!R31+'Total Notebooks (Final)'!W31 -> 85 | G31: ='Total Notebooks (Final)'!I31+'Total Notebooks (Final)'!N31+'Total Notebooks (Final)'!S31+'Total Notebooks (Final)'!X31 -> 85 | H31: ='Total Notebooks (Final)'!Z31+'Total Notebooks (Final)'!AB31+'Total Notebooks (Final)'!AD31+'Total Notebooks (Final)'!AF31+'Total Notebooks (Final)'!AH31+'Total Notebooks (Final)'!AK31 -> 536 | I31: ='Total Notebooks (Final)'!AI31+'Total Notebooks (Final)'!AL31 -> 0 | J31: =SUM(D31:I31) -> 876
B32: Hubballi | C32: GHPS Managundi | D32: ='Total Notebooks (Final)'!F32+'Total Notebooks (Final)'!K32+'Total Notebooks (Final)'!P32+'Total Notebooks (Final)'!U32 -> 206 | E32: ='Total Notebooks (Final)'!G32+'Total Notebooks (Final)'!L32+'Total Notebooks (Final)'!Q32+'Total Notebooks (Final)'!V32 -> 206 | F32: ='Total Notebooks (Final)'!H32+'Total Notebooks (Final)'!M32+'Total Notebooks (Final)'!R32+'Total Notebooks (Final)'!W32 -> 206 | G32: ='Total Notebooks (Final)'!I32+'Total Notebooks (Final)'!N32+'Total Notebooks (Final)'!S32+'Total Notebooks (Final)'!X32 -> 206 | H32: ='Total Notebooks (Final)'!Z32+'Total Notebooks (Final)'!AB32+'Total Notebooks (Final)'!AD32+'Total Notebooks (Final)'!AF32+'Total Notebooks (Final)'!AH32+'Total Notebooks (Final)'!AK32 -> 1120 | I32: ='Total Notebooks (Final)'!AI32+'Total Notebooks (Final)'!AL32 -> 0 | J32: =SUM(D32:I32) -> 1944
A33: 31 | B33: Hubballi | C33: GHS Managundi | D33: ='Total Notebooks (Final)'!F33+'Total Notebooks (Final)'!K33+'Total Notebooks (Final)'!P33+'Total Notebooks (Final)'!U33 -> 0 | E33: ='Total Notebooks (Final)'!G33+'Total Notebooks (Final)'!L33+'Total Notebooks (Final)'!Q33+'Total Notebooks (Final)'!V33 -> 0 | F33: ='Total Notebooks (Final)'!H33+'Total Notebooks (Final)'!M33+'Total Notebooks (Final)'!R33+'Total Notebooks (Final)'!W33 -> 0 | G33: ='Total Notebooks (Final)'!I33+'Total Notebooks (Final)'!N33+'Total Notebooks (Final)'!S33+'Total Notebooks (Final)'!X33 -> 0 | H33: ='Total Notebooks (Final)'!Z33+'Total Notebooks (Final)'!AB33+'Total Notebooks (Final)'!AD33+'Total Notebooks (Final)'!AF33+'Total Notebooks (Final)'!AH33+'Total Notebooks (Final)'!AK33 -> 1752 | I33: ='Total Notebooks (Final)'!AI33+'Total Notebooks (Final)'!AL33 -> 688 | J33: =SUM(D33:I33) -> 2440
A34: 32 | B34: Hubballi | C34: GHPS Yarikoppa | D34: ='Total Notebooks (Final)'!F34+'Total Notebooks (Final)'!K34+'Total Notebooks (Final)'!P34+'Total Notebooks (Final)'!U34 -> 67 | E34: ='Total Notebooks (Final)'!G34+'Total Notebooks (Final)'!L34+'Total Notebooks (Final)'!Q34+'Total Notebooks (Final)'!V34 -> 67 | F34: ='Total Notebooks (Final)'!H34+'Total Notebooks (Final)'!M34+'Total Notebooks (Final)'!R34+'Total Notebooks (Final)'!W34 -> 67 | G34: ='Total Notebooks (Final)'!I34+'Total Notebooks (Final)'!N34+'Total Notebooks (Final)'!S34+'Total Notebooks (Final)'!X34 -> 67 | H34: ='Total Notebooks (Final)'!Z34+'Total Notebooks (Final)'!AB34+'Total Notebooks (Final)'!AD34+'Total Notebooks (Final)'!AF34+'Total Notebooks (Final)'!AH34+'Total Notebooks (Final)'!AK34 -> 840 | I34: ='Total Notebooks (Final)'!AI34+'Total Notebooks (Final)'!AL34 -> 0 | J34: =SUM(D34:I34) -> 1108
A35: 33 | B35: Hubballi | C35: GHS Yarikoppa | D35: ='Total Notebooks (Final)'!F35+'Total Notebooks (Final)'!K35+'Total Notebooks (Final)'!P35+'Total Notebooks (Final)'!U35 -> 0 | E35: ='Total Notebooks (Final)'!G35+'Total Notebooks (Final)'!L35+'Total Notebooks (Final)'!Q35+'Total Notebooks (Final)'!V35 -> 0 | F35: ='Total Notebooks (Final)'!H35+'Total Notebooks (Final)'!M35+'Total Notebooks (Final)'!R35+'Total Notebooks (Final)'!W35 -> 0 | G35: ='Total Notebooks (Final)'!I35+'Total Notebooks (Final)'!N35+'Total Notebooks (Final)'!S35+'Total Notebooks (Final)'!X35 -> 0 | H35: ='Total Notebooks (Final)'!Z35+'Total Notebooks (Final)'!AB35+'Total Notebooks (Final)'!AD35+'Total Notebooks (Final)'!AF35+'Total Notebooks (Final)'!AH35+'Total Notebooks (Final)'!AK35 -> 1424 | I35: ='Total Notebooks (Final)'!AI35+'Total Notebooks (Final)'!AL35 -> 532 | J35: =SUM(D35:I35) -> 1956
A36: 40 | B36: Hubballi | C36: KHPS Hosur | D36: ='Total Notebooks (Final)'!F36+'Total Notebooks (Final)'!K36+'Total Notebooks (Final)'!P36+'Total Notebooks (Final)'!U36 -> 140 | E36: ='Total Notebooks (Final)'!G36+'Total Notebooks (Final)'!L36+'Total Notebooks (Final)'!Q36+'Total Notebooks (Final)'!V36 -> 140 | F36: ='Total Notebooks (Final)'!H36+'Total Notebooks (Final)'!M36+'Total Notebooks (Final)'!R36+'Total Notebooks (Final)'!W36 -> 140 | G36: ='Total Notebooks (Final)'!I36+'Total Notebooks (Final)'!N36+'Total Notebooks (Final)'!S36+'Total Notebooks (Final)'!X36 -> 140 | H36: ='Total Notebooks (Final)'!Z36+'Total Notebooks (Final)'!AB36+'Total Notebooks (Final)'!AD36+'Total Notebooks (Final)'!AF36+'Total Notebooks (Final)'!AH36+'Total Notebooks (Final)'!AK36 -> 896 | I36: ='Total Notebooks (Final)'!AI36+'Total Notebooks (Final)'!AL36 -> 0 | J36: =SUM(D36:I36) -> 1456
A37: 41 | B37: Belgaum | C37: Hebbal Boys School | D37: ='Total Notebooks (Final)'!F37+'Total Notebooks (Final)'!K37+'Total Notebooks (Final)'!P37+'Total Notebooks (Final)'!U37 -> 45 | E37: ='Total Notebooks (Final)'!G37+'Total Notebooks (Final)'!L37+'Total Notebooks (Final)'!Q37+'Total Notebooks (Final)'!V37 -> 45 | F37: ='Total Notebooks (Final)'!H37+'Total Notebooks (Final)'!M37+'Total Notebooks (Final)'!R37+'Total Notebooks (Final)'!W37 -> 45 | G37: ='Total Notebooks (Final)'!I37+'Total Notebooks (Final)'!N37+'Total Notebooks (Final)'!S37+'Total Notebooks (Final)'!X37 -> 45 | H37: ='Total Notebooks (Final)'!Z37+'Total Notebooks (Final)'!AB37+'Total Notebooks (Final)'!AD37+'Total Notebooks (Final)'!AF37+'Total Notebooks (Final)'!AH37+'Total Notebooks (Final)'!AK37 -> 536 | I37: ='Total Notebooks (Final)'!AI37+'Total Notebooks (Final)'!AL37 -> 0 | J37: =SUM(D37:I37) -> 716
A38: 34 | B38: Belgaum | C38: Hebbal Girls School | D38: ='Total Notebooks (Final)'!F38+'Total Notebooks (Final)'!K38+'Total Notebooks (Final)'!P38+'Total Notebooks (Final)'!U38 -> 70 | E38: ='Total Notebooks (Final)'!G38+'Total Notebooks (Final)'!L38+'Total Notebooks (Final)'!Q38+'Total Notebooks (Final)'!V38 -> 70 | F38: ='Total Notebooks (Final)'!H38+'Total Notebooks (Final)'!M38+'Total Notebooks (Final)'!R38+'Total Notebooks (Final)'!W38 -> 70 | G38: ='Total Notebooks (Final)'!I38+'Total Notebooks (Final)'!N38+'Total Notebooks (Final)'!S38+'Total Notebooks (Final)'!X38 -> 70 | H38: ='Total Notebooks (Final)'!Z38+'Total Notebooks (Final)'!AB38+'Total Notebooks (Final)'!AD38+'Total Notebooks (Final)'!AF38+'Total Notebooks (Final)'!AH38+'Total Notebooks (Final)'!AK38 -> 456 | I38: ='Total Notebooks (Final)'!AI38+'Total Notebooks (Final)'!AL38 -> 0 | J38: =SUM(D38:I38) -> 736
A39: 35 | B39: Belgaum | C39: KHPS Bidrewadi | D39: ='Total Notebooks (Final)'!F39+'Total Notebooks (Final)'!K39+'Total Notebooks (Final)'!P39+'Total Notebooks (Final)'!U39 -> 65 | E39: ='Total Notebooks (Final)'!G39+'Total Notebooks (Final)'!L39+'Total Notebooks (Final)'!Q39+'Total Notebooks (Final)'!V39 -> 65 | F39: ='Total Notebooks (Final)'!H39+'Total Notebooks (Final)'!M39+'Total Notebooks (Final)'!R39+'Total Notebooks (Final)'!W39 -> 65 | G39: ='Total Notebooks (Final)'!I39+'Total Notebooks (Final)'!N39+'Total Notebooks (Final)'!S39+'Total Notebooks (Final)'!X39 -> 65 | H39: ='Total Notebooks (Final)'!Z39+'Total Notebooks (Final)'!AB39+'Total Notebooks (Final)'!AD39+'Total Notebooks (Final)'!AF39+'Total Notebooks (Final)'!AH39+'Total Notebooks (Final)'!AK39 -> 488 | I39: ='Total Notebooks (Final)'!AI39+'Total Notebooks (Final)'!AL39 -> 0 | J39: =SUM(D39:I39) -> 748
A40: 36 | B40: Belgaum | C40: KHPS Vaarimastiholli | D40: ='Total Notebooks (Final)'!F40+'Total Notebooks (Final)'!K40+'Total Notebooks (Final)'!P40+'Total Notebooks (Final)'!U40 -> 32 | E40: ='Total Notebooks (Final)'!G40+'Total Notebooks (Final)'!L40+'Total Notebooks (Final)'!Q40+'Total Notebooks (Final)'!V40 -> 32 | F40: ='Total Notebooks (Final)'!H40+'Total Notebooks (Final)'!M40+'Total Notebooks (Final)'!R40+'Total Notebooks (Final)'!W40 -> 32 | G40: ='Total Notebooks (Final)'!I40+'Total Notebooks (Final)'!N40+'Total Notebooks (Final)'!S40+'Total Notebooks (Final)'!X40 -> 32 | H40: ='Total Notebooks (Final)'!Z40+'Total Notebooks (Final)'!AB40+'Total Notebooks (Final)'!AD40+'Total Notebooks (Final)'!AF40+'Total Notebooks (Final)'!AH40+'Total Notebooks (Final)'!AK40 -> 272 | I40: ='Total Notebooks (Final)'!AI40+'Total Notebooks (Final)'!AL40 -> 0 | J40: =SUM(D40:I40) -> 400
A41: 37 | B41: Belgaum | C41: UHPS Ullagadikhanapur | D41: ='Total Notebooks (Final)'!F41+'Total Notebooks (Final)'!K41+'Total Notebooks (Final)'!P41+'Total Notebooks (Final)'!U41 -> 119 | E41: ='Total Notebooks (Final)'!G41+'Total Notebooks (Final)'!L41+'Total Notebooks (Final)'!Q41+'Total Notebooks (Final)'!V41 -> 119 | F41: ='Total Notebooks (Final)'!H41+'Total Notebooks (Final)'!M41+'Total Notebooks (Final)'!R41+'Total Notebooks (Final)'!W41 -> 119 | G41: ='Total Notebooks (Final)'!I41+'Total Notebooks (Final)'!N41+'Total Notebooks (Final)'!S41+'Total Notebooks (Final)'!X41 -> 119 | H41: ='Total Notebooks (Final)'!Z41+'Total Notebooks (Final)'!AB41+'Total Notebooks (Final)'!AD41+'Total Notebooks (Final)'!AF41+'Total Notebooks (Final)'!AH41+'Total Notebooks (Final)'!AK41 -> 664 | I41: ='Total Notebooks (Final)'!AI41+'Total Notebooks (Final)'!AL41 -> 0 | J41: =SUM(D41:I41) -> 1140
A42: 38 | B42: Hubballi | C42: GHS Hosur | D42: ='Total Notebooks (Final)'!F42+'Total Notebooks (Final)'!K42+'Total Notebooks (Final)'!P42+'Total Notebooks (Final)'!U42 -> 0 | E42: ='Total Notebooks (Final)'!G42+'Total Notebooks (Final)'!L42+'Total Notebooks (Final)'!Q42+'Total Notebooks (Final)'!V42 -> 0 | F42: ='Total Notebooks (Final)'!H42+'Total Notebooks (Final)'!M42+'Total Notebooks (Final)'!R42+'Total Notebooks (Final)'!W42 -> 0 | G42: ='Total Notebooks (Final)'!I42+'Total Notebooks (Final)'!N42+'Total Notebooks (Final)'!S42+'Total Notebooks (Final)'!X42 -> 0 | H42: ='Total Notebooks (Final)'!Z42+'Total Notebooks (Final)'!AB42+'Total Notebooks (Final)'!AD42+'Total Notebooks (Final)'!AF42+'Total Notebooks (Final)'!AH42+'Total Notebooks (Final)'!AK42 -> 1024 | I42: ='Total Notebooks (Final)'!AI42+'Total Notebooks (Final)'!AL42 -> 360 | J42: =SUM(D42:I42) -> 1384
A43: 39 | B43: Hubballi | C43: GHS Itigatti Hubballi | D43: ='Total Notebooks (Final)'!F43+'Total Notebooks (Final)'!K43+'Total Notebooks (Final)'!P43+'Total Notebooks (Final)'!U43 -> 0 | E43: ='Total Notebooks (Final)'!G43+'Total Notebooks (Final)'!L43+'Total Notebooks (Final)'!Q43+'Total Notebooks (Final)'!V43 -> 0 | F43: ='Total Notebooks (Final)'!H43+'Total Notebooks (Final)'!M43+'Total Notebooks (Final)'!R43+'Total Notebooks (Final)'!W43 -> 0 | G43: ='Total Notebooks (Final)'!I43+'Total Notebooks (Final)'!N43+'Total Notebooks (Final)'!S43+'Total Notebooks (Final)'!X43 -> 0 | H43: ='Total Notebooks (Final)'!Z43+'Total Notebooks (Final)'!AB43+'Total Notebooks (Final)'!AD43+'Total Notebooks (Final)'!AF43+'Total Notebooks (Final)'!AH43+'Total Notebooks (Final)'!AK43 -> 1232 | I43: ='Total Notebooks (Final)'!AI43+'Total Notebooks (Final)'!AL43 -> 416 | J43: =SUM(D43:I43) -> 1648
